File: Data/Ni2piv8_DC1kOedown.dc.dat
[Header]
TITLE,MPMS DC Measurement
BYAPP,MPMS Measurement,2.1,Summary
FILEOPENTIME, 1357729182.234000 1/9/2013, 10:59:42 AM

INFO, APPNAME, MPMS MultiVu Application, Revision 1.56,  Build 67

INFO, NAME, C2-107
INFO, WEIGHT, 21.240
INFO, AREA, 1.000
INFO, LENGTH, 1.000
INFO, SHAPE, 0
INFO, COMMENT, JPSW, gel cap, with tape, no eico
INFO, SEQUENCE FILE: StdDC_Mag_short_matched.seq


INFO, BACKGROUND DATA FILE:, None


STARTUPAXIS,X,4,LINEAR,AUTO,0.000000,0.000000
STARTUPAXIS,Y1,5,LINEAR,AUTO,0.000000,0.000000


STARTUPGROUP,Longitudinal
FIELDGROUP,Longitudinal,1,2,3,4,5,6,7,8,9,15,16,17,18,27,28
FIELDGROUP,Transverse,1,2,3,4,10,11,12,13,14,19,20,21,22,27,28

PLOT_APPEARANCE,ALL,HORZ_GRID_ON,VERT_GRID_ON,MARKERS_AND_LINES

[Data]
Time,Comment,Field (Oe),Temperature (K),Long Moment (emu),Long Scan Std Dev,Long Algorithm,Long Reg Fit,Long Percent Error (%),Trans Moment (emu),Trans Scan Std Dev,Trans Algorithm,Trans Reg Fit,Trans Percent Error (%),Long Moment [w/o ABS] (emu),Long Scan Std Dev [w/o ABS],Long Reg Fit [w/o ABS],Long Percent Error [w/o ABS] (%),Trans Moment [w/o ABS] (emu),Trans Scan Std Dev [w/o ABS],Trans Reg Fit [w/o ABS],Trans Percent Error [w/o ABS] (%),Points per Scan,Scans per Measurement,Scan Length (cm),Delta Temp (K),Rot Position (deg),Error,EC Comp. Running,Using ABS,
1357729182.234,,1.000000e+003,2.999944e+002,1.802660e-004,4.709848e-008,3,9.785087e-001,2.612721e-002,,,,,,,,,,,,,,24,3,4.000000e+000,1.202393e-002,0.000000e+000,0,,0,
1357729730.609,,1.000000e+003,2.901457e+002,1.890264e-004,1.027296e-006,3,9.800830e-001,5.434667e-001,,,,,,,,,,,,,,24,3,4.000000e+000,1.777039e-001,0.000000e+000,0,,0,
1357730032.296,,1.000000e+003,2.795913e+002,1.966082e-004,1.195012e-006,3,9.808405e-001,6.078137e-001,,,,,,,,,,,,,,24,3,4.000000e+000,4.640198e-001,0.000000e+000,0,,0,
1357730328.734,,1.000000e+003,2.696073e+002,2.043141e-004,1.090222e-006,3,9.814146e-001,5.336009e-001,,,,,,,,,,,,,,24,3,4.000000e+000,4.120178e-001,0.000000e+000,0,,0,
1357730623.484,,1.000000e+003,2.595963e+002,2.129493e-004,1.235244e-006,3,9.807294e-001,5.800651e-001,,,,,,,,,,,,,,24,3,4.000000e+000,4.175110e-001,0.000000e+000,0,,0,
1357730926.359,,1.000000e+003,2.496356e+002,2.220221e-004,1.408312e-006,3,9.817772e-001,6.343116e-001,,,,,,,,,,,,,,24,3,4.000000e+000,3.542023e-001,0.000000e+000,0,,0,
1357731248.734,,1.000000e+003,2.396795e+002,2.318359e-004,1.282929e-006,3,9.824391e-001,5.533780e-001,,,,,,,,,,,,,,24,3,4.000000e+000,3.502045e-001,0.000000e+000,0,,0,
1357731580.109,,1.000000e+003,2.297328e+002,2.426758e-004,1.410318e-006,3,9.829491e-001,5.811532e-001,,,,,,,,,,,,,,24,3,4.000000e+000,3.298035e-001,0.000000e+000,0,,0,
1357731917.312,,1.000000e+003,2.197653e+002,2.504455e-004,7.175866e-006,3,9.067295e-001,2.865240e+000,,,,,,,,,,,,,,24,3,4.000000e+000,3.097076e-001,0.000000e+000,0,,0,
1357732238.125,,1.000000e+003,2.097911e+002,2.678751e-004,1.814100e-006,3,9.830782e-001,6.772184e-001,,,,,,,,,,,,,,24,3,4.000000e+000,3.249969e-001,0.000000e+000,0,,0,
1357732549.750,,1.000000e+003,1.997835e+002,2.821790e-004,1.782363e-006,3,9.841617e-001,6.316428e-001,,,,,,,,,,,,,,24,3,4.000000e+000,2.964935e-001,0.000000e+000,0,,0,
1357732866.500,,1.000000e+003,1.898140e+002,2.980485e-004,1.961252e-006,3,9.847468e-001,6.580312e-001,,,,,,,,,,,,,,24,3,4.000000e+000,2.938080e-001,0.000000e+000,0,,0,
1357733187.484,,1.000000e+003,1.798586e+002,3.155428e-004,2.038028e-006,3,9.850041e-001,6.458799e-001,,,,,,,,,,,,,,24,3,4.000000e+000,2.834015e-001,0.000000e+000,0,,0,
1357733513.875,,1.000000e+003,1.699032e+002,3.313967e-004,7.613381e-006,3,9.280021e-001,2.297362e+000,,,,,,,,,,,,,,24,3,4.000000e+000,2.431030e-001,0.000000e+000,0,,0,
1357733839.859,,1.000000e+003,1.599290e+002,3.581486e-004,2.111055e-006,3,9.851668e-001,5.894353e-001,,,,,,,,,,,,,,24,3,4.000000e+000,2.282104e-001,0.000000e+000,0,,0,
1357734169.609,,1.000000e+003,1.499552e+002,4.125830e-004,4.747053e-005,3,9.189646e-001,1.150569e+001,,,,,,,,,,,,,,24,3,4.000000e+000,1.965027e-001,0.000000e+000,0,,0,
1357734577.359,,1.000000e+003,1.400548e+002,4.104202e-004,2.165026e-007,3,9.865906e-001,5.275144e-002,,,,,,,,,,,,,,24,3,4.000000e+000,2.520752e-002,0.000000e+000,0,,0,
1357734907.984,,1.000000e+003,1.299915e+002,4.050696e-004,7.548385e-005,3,8.815503e-001,1.863478e+001,,,,,,,,,,,,,,24,3,4.000000e+000,1.233063e-001,0.000000e+000,0,,0,
1357735232.593,,1.000000e+003,1.199837e+002,4.634926e-004,5.361461e-005,3,9.199634e-001,1.156752e+001,,,,,,,,,,,,,,24,3,4.000000e+000,1.365967e-001,0.000000e+000,0,,0,
1357735551.250,,1.000000e+003,1.099897e+002,5.351775e-004,3.747180e-006,3,9.866874e-001,7.001751e-001,,,,,,,,,,,,,,24,3,4.000000e+000,1.091995e-001,0.000000e+000,0,,0,
1357735861.375,,1.000000e+003,9.999012e+001,5.932458e-004,4.428687e-006,3,9.873630e-001,7.465180e-001,,,,,,,,,,,,,,24,3,4.000000e+000,8.297729e-002,0.000000e+000,0,,0,
1357736167.109,,1.000000e+003,9.000759e+001,6.637857e-004,4.909803e-006,3,9.879966e-001,7.396669e-001,,,,,,,,,,,,,,24,3,4.000000e+000,9.154510e-002,0.000000e+000,0,,0,
1357736480.328,,1.000000e+003,8.005636e+001,7.784432e-004,4.305018e-005,3,9.707031e-001,5.530292e+000,,,,,,,,,,,,,,24,3,4.000000e+000,3.098297e-002,0.000000e+000,0,,0,
1357736765.484,,1.000000e+003,7.497140e+001,8.040212e-004,3.478757e-006,3,9.890066e-001,4.326698e-001,,,,,,,,,,,,,,24,3,4.000000e+000,9.342957e-002,0.000000e+000,0,,0,
1357737077.687,,1.000000e+003,7.004988e+001,8.643868e-004,2.216292e-006,3,9.894044e-001,2.564004e-001,,,,,,,,,,,,,,24,3,4.000000e+000,3.231812e-002,0.000000e+000,0,,0,
1357737314.875,,1.000000e+003,6.507330e+001,9.377266e-004,3.746924e-006,3,9.894506e-001,3.995753e-001,,,,,,,,,,,,,,24,3,4.000000e+000,7.057190e-003,0.000000e+000,0,,0,
1357737590.625,,1.000000e+003,6.005763e+001,1.012470e-003,2.396200e-007,3,9.896311e-001,2.366687e-002,,,,,,,,,,,,,,24,3,4.000000e+000,2.684021e-002,0.000000e+000,0,,0,
1357737867.390,,1.000000e+003,5.502684e+001,1.113259e-003,1.224227e-006,3,9.897451e-001,1.099678e-001,,,,,,,,,,,,,,24,3,4.000000e+000,5.398941e-002,0.000000e+000,0,,0,
1357738090.031,,1.000000e+003,5.005530e+001,1.235268e-003,1.789222e-006,3,9.896867e-001,1.448448e-001,,,,,,,,,,,,,,24,3,4.000000e+000,7.159042e-002,0.000000e+000,0,,0,
1357738314.875,,1.000000e+003,4.502217e+001,1.386249e-003,1.056040e-006,3,9.897204e-001,7.617970e-002,,,,,,,,,,,,,,24,3,4.000000e+000,1.723099e-002,0.000000e+000,0,,0,
1357738539.421,,1.000000e+003,4.000965e+001,1.553522e-003,4.216340e-005,3,9.779938e-001,2.714053e+000,,,,,,,,,,,,,,24,3,4.000000e+000,3.118896e-002,0.000000e+000,0,,0,
1357738781.328,,1.000000e+003,3.499679e+001,1.819758e-003,5.720321e-005,3,9.671354e-001,3.143451e+000,,,,,,,,,,,,,,24,3,4.000000e+000,2.800751e-002,0.000000e+000,0,,0,
1357739001.500,,1.000000e+003,3.000294e+001,2.176043e-003,9.662318e-007,3,9.899312e-001,4.440317e-002,,,,,,,,,,,,,,24,3,4.000000e+000,4.688072e-002,0.000000e+000,0,,0,
1357739187.484,,1.000000e+003,2.799173e+001,2.318792e-003,6.104870e-005,3,9.808195e-001,2.632780e+000,,,,,,,,,,,,,,24,3,4.000000e+000,1.848984e-002,0.000000e+000,0,,0,
1357739369.234,,1.000000e+003,2.599302e+001,2.560911e-003,2.175265e-007,3,9.900357e-001,8.494105e-003,,,,,,,,,,,,,,24,3,4.000000e+000,1.870918e-002,0.000000e+000,0,,0,
1357739575.109,,1.000000e+003,2.399394e+001,2.806403e-003,1.667731e-006,3,9.900851e-001,5.942595e-002,,,,,,,,,,,,,,24,3,4.000000e+000,1.901054e-002,0.000000e+000,0,,0,
1357739821.125,,1.000000e+003,2.199474e+001,3.099585e-003,6.481772e-007,3,9.901423e-001,2.091174e-002,,,,,,,,,,,,,,24,3,4.000000e+000,1.231003e-002,0.000000e+000,0,,0,
1357740061.984,,1.000000e+003,1.999850e+001,3.458407e-003,4.178478e-007,3,9.902337e-001,1.208209e-002,,,,,,,,,,,,,,24,3,4.000000e+000,6.299973e-003,0.000000e+000,0,,0,
1357740293.234,,1.000000e+003,1.800034e+001,3.906379e-003,2.811168e-007,3,9.903094e-001,7.196352e-003,,,,,,,,,,,,,,24,3,4.000000e+000,3.841400e-003,0.000000e+000,0,,0,
1357740519.234,,1.000000e+003,1.600060e+001,4.478626e-003,1.475364e-007,3,9.903707e-001,3.294233e-003,,,,,,,,,,,,,,24,3,4.000000e+000,9.089470e-003,0.000000e+000,0,,0,
1357740720.984,,1.000000e+003,1.399957e+001,5.226976e-003,6.040628e-007,3,9.905010e-001,1.155664e-002,,,,,,,,,,,,,,24,3,4.000000e+000,1.680374e-003,0.000000e+000,0,,0,
1357740875.250,,1.000000e+003,1.300218e+001,5.689462e-003,1.931463e-006,3,9.905374e-001,3.394807e-002,,,,,,,,,,,,,,24,3,4.000000e+000,1.146984e-002,0.000000e+000,0,,0,
1357741026.625,,1.000000e+003,1.200013e+001,6.233646e-003,1.359366e-006,3,9.906306e-001,2.180692e-002,,,,,,,,,,,,,,24,3,4.000000e+000,1.156998e-002,0.000000e+000,0,,0,
1357741188.734,,1.000000e+003,1.100844e+001,6.871488e-003,4.681637e-005,3,9.899712e-001,6.813134e-001,,,,,,,,,,,,,,24,3,4.000000e+000,1.045990e-002,0.000000e+000,0,,0,
1357741334.718,,1.000000e+003,1.000782e+001,7.695116e-003,5.948979e-006,3,9.907544e-001,7.730851e-002,,,,,,,,,,,,,,24,3,4.000000e+000,1.880741e-002,0.000000e+000,0,,0,
1357741492.703,,1.000000e+003,9.004063e+000,8.686017e-003,4.693253e-006,3,9.908226e-001,5.403228e-002,,,,,,,,,,,,,,24,3,4.000000e+000,1.582336e-002,0.000000e+000,0,,0,
1357741650.578,,1.000000e+003,8.006626e+000,9.952012e-003,4.410500e-005,3,9.901635e-001,4.431767e-001,,,,,,,,,,,,,,24,3,4.000000e+000,1.542759e-002,0.000000e+000,0,,0,
1357741800.500,,1.000000e+003,7.010870e+000,1.151849e-002,1.481836e-005,3,9.908175e-001,1.286485e-001,,,,,,,,,,,,,,24,3,4.000000e+000,1.374865e-002,0.000000e+000,0,,0,
1357741950.203,,1.000000e+003,6.007809e+000,1.361039e-002,3.488121e-005,3,9.897527e-001,2.562838e-001,,,,,,,,,,,,,,24,3,4.000000e+000,1.424408e-002,0.000000e+000,0,,0,
1357742090.203,,1.000000e+003,5.500985e+000,1.501549e-002,2.784846e-005,3,9.916837e-001,1.854649e-001,,,,,,,,,,,,,,24,3,4.000000e+000,4.617214e-003,0.000000e+000,0,,0,
1357742241.203,,1.000000e+003,4.998919e+000,1.660653e-002,1.722230e-005,3,9.908993e-001,1.037080e-001,,,,,,,,,,,,,,24,3,4.000000e+000,4.292011e-003,0.000000e+000,0,,0,
1357742553.578,,1.000000e+003,4.495885e+000,1.863402e-002,1.116716e-005,3,9.909604e-001,5.992891e-002,,,,,,,,,,,,,,24,3,4.000000e+000,1.423359e-003,0.000000e+000,0,,0,
1357742719.359,,1.000000e+003,3.994282e+000,2.117841e-002,3.939701e-005,3,9.909444e-001,1.860244e-001,,,,,,,,,,,,,,24,3,4.000000e+000,1.675844e-003,0.000000e+000,0,,0,
1357742853.421,,1.000000e+003,3.496335e+000,2.430387e-002,3.526893e-005,3,9.909126e-001,1.451165e-001,,,,,,,,,,,,,,24,3,4.000000e+000,5.958080e-003,0.000000e+000,0,,0,
1357743035.906,,1.000000e+003,2.999309e+000,2.848558e-002,6.210924e-005,3,9.910627e-001,2.180375e-001,,,,,,,,,,,,,,24,3,4.000000e+000,1.039028e-003,0.000000e+000,0,,0,
1357743240.687,,1.000000e+003,2.499996e+000,3.423581e-002,1.285884e-004,3,9.908831e-001,3.755962e-001,,,,,,,,,,,,,,24,3,4.000000e+000,2.558947e-003,0.000000e+000,0,,0,
1357743553.671,,1.000000e+003,1.997117e+000,4.337012e-002,2.329397e-005,3,9.909536e-001,5.370972e-002,,,,,,,,,,,,,,24,3,4.000000e+000,4.577994e-003,0.000000e+000,0,,0,