File: Data/Ni2pic2_DC1kOedown.dc.dat
[Header]
TITLE,MPMS DC Measurement
BYAPP,MPMS Measurement,2.1,Summary
FILEOPENTIME, 1363866538.437000 3/21/2013, 11:48:58 AM

INFO, APPNAME, MPMS MultiVu Application, Revision 1.56,  Build 67

INFO, NAME, C2-106
INFO, WEIGHT, 30.310
INFO, AREA, 1.000
INFO, LENGTH, 1.000
INFO, SHAPE, 0
INFO, COMMENT, no eico
INFO, SEQUENCE FILE: StdDC_Mag_long_matched.seq


INFO, BACKGROUND DATA FILE:, None


STARTUPAXIS,X,4,LINEAR,AUTO,0.000000,0.000000
STARTUPAXIS,Y1,5,LINEAR,AUTO,0.000000,0.000000


STARTUPGROUP,Longitudinal
FIELDGROUP,Longitudinal,1,2,3,4,5,6,7,8,9,15,16,17,18,27,28
FIELDGROUP,Transverse,1,2,3,4,10,11,12,13,14,19,20,21,22,27,28

PLOT_APPEARANCE,ALL,HORZ_GRID_ON,VERT_GRID_ON,MARKERS_AND_LINES

[Data]
Time,Comment,Field (Oe),Temperature (K),Long Moment (emu),Long Scan Std Dev,Long Algorithm,Long Reg Fit,Long Percent Error (%),Trans Moment (emu),Trans Scan Std Dev,Trans Algorithm,Trans Reg Fit,Trans Percent Error (%),Long Moment [w/o ABS] (emu),Long Scan Std Dev [w/o ABS],Long Reg Fit [w/o ABS],Long Percent Error [w/o ABS] (%),Trans Moment [w/o ABS] (emu),Trans Scan Std Dev [w/o ABS],Trans Reg Fit [w/o ABS],Trans Percent Error [w/o ABS] (%),Points per Scan,Scans per Measurement,Scan Length (cm),Delta Temp (K),Rot Position (deg),Error,EC Comp. Running,Using ABS,
1363866538.437,,1.000000e+003,3.000012e+002,2.641687e-004,1.269483e-007,3,9.839422e-001,4.805579e-002,,,,,,,,,,,,,,24,3,4.000000e+000,5.941772e-002,0.000000e+000,0,,0,
1363867081.562,,1.000000e+003,2.901331e+002,2.761713e-004,1.298353e-006,3,9.836988e-001,4.701262e-001,,,,,,,,,,,,,,24,3,4.000000e+000,1.665955e-001,0.000000e+000,0,,0,
1363867391.312,,1.000000e+003,2.795722e+002,2.869516e-004,1.717823e-006,3,9.841902e-001,5.986455e-001,,,,,,,,,,,,,,24,3,4.000000e+000,4.226990e-001,0.000000e+000,0,,0,
1363867677.625,,1.000000e+003,2.695603e+002,2.981233e-004,1.795922e-006,3,9.853511e-001,6.024090e-001,,,,,,,,,,,,,,24,3,4.000000e+000,4.118958e-001,0.000000e+000,0,,0,
1363867964.859,,1.000000e+003,2.595686e+002,3.101842e-004,1.915143e-006,3,9.857585e-001,6.174213e-001,,,,,,,,,,,,,,24,3,4.000000e+000,4.351196e-001,0.000000e+000,0,,0,
1363868275.046,,1.000000e+003,2.496313e+002,3.223425e-004,1.878296e-006,3,9.853122e-001,5.827017e-001,,,,,,,,,,,,,,24,3,4.000000e+000,3.706055e-001,0.000000e+000,0,,0,
1363868591.312,,1.000000e+003,2.396853e+002,3.365056e-004,2.096777e-006,3,9.856197e-001,6.231031e-001,,,,,,,,,,,,,,24,3,4.000000e+000,3.807068e-001,0.000000e+000,0,,0,
1363868919.171,,1.000000e+003,2.297165e+002,3.512102e-004,1.880106e-006,3,9.863098e-001,5.353221e-001,,,,,,,,,,,,,,24,3,4.000000e+000,2.875977e-001,0.000000e+000,0,,0,
1363869241.296,,1.000000e+003,2.197274e+002,3.683802e-004,2.357402e-006,3,9.868426e-001,6.399371e-001,,,,,,,,,,,,,,24,3,4.000000e+000,3.482971e-001,0.000000e+000,0,,0,
1363869581.546,,1.000000e+003,2.097627e+002,3.857620e-004,2.091015e-006,3,9.871159e-001,5.420479e-001,,,,,,,,,,,,,,24,3,4.000000e+000,2.541046e-001,0.000000e+000,0,,0,
1363869914.171,,1.000000e+003,1.998290e+002,4.060630e-004,2.504328e-006,3,9.865149e-001,6.167340e-001,,,,,,,,,,,,,,24,3,4.000000e+000,3.020020e-001,0.000000e+000,0,,0,
1363870239.312,,1.000000e+003,1.898239e+002,4.282658e-004,2.720079e-006,3,9.872155e-001,6.351380e-001,,,,,,,,,,,,,,24,3,4.000000e+000,2.498016e-001,0.000000e+000,0,,0,
1363870568.296,,1.000000e+003,1.798567e+002,4.525109e-004,2.912855e-006,3,9.878497e-001,6.437094e-001,,,,,,,,,,,,,,24,3,4.000000e+000,2.435150e-001,0.000000e+000,0,,0,
1363870899.187,,1.000000e+003,1.699090e+002,4.804958e-004,3.059157e-006,3,9.883149e-001,6.366668e-001,,,,,,,,,,,,,,24,3,4.000000e+000,2.312012e-001,0.000000e+000,0,,0,
1363871234.187,,1.000000e+003,1.599290e+002,5.109938e-004,3.298226e-006,3,9.880719e-001,6.454533e-001,,,,,,,,,,,,,,24,3,4.000000e+000,2.174988e-001,0.000000e+000,0,,0,
1363871567.046,,1.000000e+003,1.499489e+002,5.463248e-004,3.650806e-006,3,9.877655e-001,6.682483e-001,,,,,,,,,,,,,,24,3,4.000000e+000,1.775055e-001,0.000000e+000,0,,0,
1363871899.671,,1.000000e+003,1.399581e+002,5.870383e-004,3.937172e-006,3,9.883499e-001,6.706840e-001,,,,,,,,,,,,,,24,3,4.000000e+000,1.513062e-001,0.000000e+000,0,,0,
1363872233.812,,1.000000e+003,1.299705e+002,6.258099e-004,1.491704e-005,3,9.809368e-001,2.383637e+000,,,,,,,,,,,,,,24,3,4.000000e+000,9.379578e-002,0.000000e+000,0,,0,
1363872562.921,,1.000000e+003,1.199693e+002,6.875950e-004,4.630208e-006,3,9.896701e-001,6.733917e-001,,,,,,,,,,,,,,24,3,4.000000e+000,1.324005e-001,0.000000e+000,0,,0,
1363872886.312,,1.000000e+003,1.099800e+002,7.521745e-004,5.181175e-006,3,9.898605e-001,6.888263e-001,,,,,,,,,,,,,,24,3,4.000000e+000,9.829712e-002,0.000000e+000,0,,0,
1363873204.062,,1.000000e+003,9.998456e+001,8.294369e-004,5.833370e-006,3,9.894642e-001,7.032928e-001,,,,,,,,,,,,,,24,3,4.000000e+000,1.014252e-001,0.000000e+000,0,,0,
1363873538.500,,1.000000e+003,9.003601e+001,9.137720e-004,1.761413e-006,3,9.892628e-001,1.927629e-001,,,,,,,,,,,,,,24,3,4.000000e+000,8.392334e-002,0.000000e+000,0,,0,
1363873858.921,,1.000000e+003,8.005834e+001,1.034943e-003,5.947917e-006,3,9.897699e-001,5.747098e-001,,,,,,,,,,,,,,24,3,4.000000e+000,2.269745e-002,0.000000e+000,0,,0,
1363874151.562,,1.000000e+003,7.497231e+001,1.103549e-003,4.229378e-006,3,9.902899e-001,3.832526e-001,,,,,,,,,,,,,,24,3,4.000000e+000,8.974457e-002,0.000000e+000,0,,0,
1363874472.187,,1.000000e+003,7.004883e+001,1.181938e-003,2.980385e-006,3,9.907430e-001,2.521610e-001,,,,,,,,,,,,,,24,3,4.000000e+000,3.231812e-002,0.000000e+000,0,,0,
1363874719.062,,1.000000e+003,6.506721e+001,1.277006e-003,4.446489e-006,3,9.908952e-001,3.481965e-001,,,,,,,,,,,,,,24,3,4.000000e+000,1.271057e-002,0.000000e+000,0,,0,
1363874956.296,,1.000000e+003,6.006638e+001,1.385721e-003,4.195012e-006,3,9.911351e-001,3.027312e-001,,,,,,,,,,,,,,24,3,4.000000e+000,9.757996e-003,0.000000e+000,0,,0,
1363875186.546,,1.000000e+003,5.506665e+001,1.514583e-003,3.211105e-006,3,9.914165e-001,2.120125e-001,,,,,,,,,,,,,,24,3,4.000000e+000,1.870728e-002,0.000000e+000,0,,0,
1363875414.187,,1.000000e+003,5.004715e+001,1.670613e-003,2.249642e-006,3,9.916019e-001,1.346597e-001,,,,,,,,,,,,,,24,3,4.000000e+000,5.057907e-002,0.000000e+000,0,,0,
1363875659.562,,1.000000e+003,4.501666e+001,1.861988e-003,1.485300e-007,3,9.919470e-001,7.976959e-003,,,,,,,,,,,,,,24,3,4.000000e+000,1.866913e-002,0.000000e+000,0,,0,
1363875884.671,,1.000000e+003,4.001601e+001,2.105083e-003,3.691976e-007,3,9.922023e-001,1.753838e-002,,,,,,,,,,,,,,24,3,4.000000e+000,2.773285e-002,0.000000e+000,0,,0,
1363876107.421,,1.000000e+003,3.500101e+001,2.420602e-003,2.168117e-007,3,9.923672e-001,8.956932e-003,,,,,,,,,,,,,,24,3,4.000000e+000,4.879761e-002,0.000000e+000,0,,0,
1363876332.671,,1.000000e+003,3.000714e+001,2.843549e-003,1.697864e-006,3,9.924887e-001,5.970933e-002,,,,,,,,,,,,,,24,3,4.000000e+000,4.689980e-002,0.000000e+000,0,,0,
1363876523.171,,1.000000e+003,2.799512e+001,3.058983e-003,3.246006e-007,3,9.925577e-001,1.061139e-002,,,,,,,,,,,,,,24,3,4.000000e+000,1.611900e-002,0.000000e+000,0,,0,
1363876707.046,,1.000000e+003,2.599614e+001,3.307387e-003,5.532065e-007,3,9.926351e-001,1.672639e-002,,,,,,,,,,,,,,24,3,4.000000e+000,8.840561e-003,0.000000e+000,0,,0,
1363876913.156,,1.000000e+003,2.399264e+001,3.600538e-003,1.702830e-006,3,9.926264e-001,4.729376e-002,,,,,,,,,,,,,,24,3,4.000000e+000,2.124977e-002,0.000000e+000,0,,0,
1363877093.875,,1.000000e+003,2.206744e+001,3.933070e-003,4.375499e-006,3,9.926908e-001,1.112490e-001,,,,,,,,,,,,,,24,3,4.000000e+000,7.043839e-002,0.000000e+000,0,,0,
1363877273.671,,1.000000e+003,2.006015e+001,4.352477e-003,2.300490e-006,3,9.927306e-001,5.285473e-002,,,,,,,,,,,,,,24,3,4.000000e+000,2.140045e-002,0.000000e+000,0,,0,
1363877488.734,,1.000000e+003,1.802848e+001,4.871327e-003,6.390888e-006,3,9.927114e-001,1.311940e-001,,,,,,,,,,,,,,24,3,4.000000e+000,5.655861e-002,0.000000e+000,0,,0,
1363877653.562,,1.000000e+003,1.603681e+001,5.519224e-003,4.682711e-006,3,9.928234e-001,8.484365e-002,,,,,,,,,,,,,,24,3,4.000000e+000,2.436066e-002,0.000000e+000,0,,0,
1363877812.062,,1.000000e+003,1.401505e+001,6.364383e-003,1.841884e-006,3,9.929275e-001,2.894049e-002,,,,,,,,,,,,,,24,3,4.000000e+000,7.340431e-003,0.000000e+000,0,,0,
1363877963.187,,1.000000e+003,1.300751e+001,6.881957e-003,4.260844e-006,3,9.928920e-001,6.191326e-002,,,,,,,,,,,,,,24,3,4.000000e+000,1.655006e-002,0.000000e+000,0,,0,
1363878119.312,,1.000000e+003,1.200874e+001,7.471003e-003,7.908212e-006,3,9.928979e-001,1.058521e-001,,,,,,,,,,,,,,24,3,4.000000e+000,1.959038e-002,0.000000e+000,0,,0,
1363878262.640,,1.000000e+003,1.102286e+001,8.131076e-003,9.069913e-005,3,9.892869e-001,1.115463e+000,,,,,,,,,,,,,,24,3,4.000000e+000,1.169968e-002,0.000000e+000,0,,0,
1363878415.421,,1.000000e+003,1.001123e+001,9.044209e-003,4.349486e-006,3,9.930182e-001,4.809140e-002,,,,,,,,,,,,,,24,3,4.000000e+000,7.100105e-003,0.000000e+000,0,,0,
1363878566.062,,1.000000e+003,9.009420e+000,1.008786e-002,3.461616e-006,3,9.930132e-001,3.431468e-002,,,,,,,,,,,,,,24,3,4.000000e+000,5.449295e-003,0.000000e+000,0,,0,
1363878715.781,,1.000000e+003,8.006580e+000,1.138056e-002,2.766940e-006,3,9.930153e-001,2.431287e-002,,,,,,,,,,,,,,24,3,4.000000e+000,4.171371e-003,0.000000e+000,0,,0,
1363878856.078,,1.000000e+003,7.003366e+000,1.301958e-002,3.572365e-006,3,9.930041e-001,2.743841e-002,,,,,,,,,,,,,,24,3,4.000000e+000,6.944656e-003,0.000000e+000,0,,0,
1363878999.953,,1.000000e+003,6.000463e+000,1.512527e-002,5.696384e-006,3,9.929946e-001,3.766138e-002,,,,,,,,,,,,,,24,3,4.000000e+000,3.373146e-003,0.000000e+000,0,,0,
1363879142.968,,1.000000e+003,5.499651e+000,1.644058e-002,4.604347e-006,3,9.930677e-001,2.800599e-002,,,,,,,,,,,,,,24,3,4.000000e+000,2.803802e-003,0.000000e+000,0,,0,
1363879348.328,,1.000000e+003,5.007659e+000,1.794419e-002,1.632771e-006,3,9.930830e-001,9.099163e-003,,,,,,,,,,,,,,24,3,4.000000e+000,6.365776e-003,0.000000e+000,0,,0,
1363881904.953,,1.000000e+003,4.510876e+000,1.979294e-002,1.285137e-006,3,9.931731e-001,6.492907e-003,,,,,,,,,,,,,,24,3,4.000000e+000,2.378941e-003,0.000000e+000,0,,0,
1363882071.015,,1.000000e+003,3.997571e+000,2.203555e-002,1.439167e-005,3,9.930944e-001,6.531117e-002,,,,,,,,,,,,,,24,3,4.000000e+000,7.557869e-004,0.000000e+000,0,,0,
1363882201.328,,1.000000e+003,3.496168e+000,2.454218e-002,5.835634e-006,3,9.931133e-001,2.377797e-002,,,,,,,,,,,,,,24,3,4.000000e+000,2.554893e-003,0.000000e+000,0,,0,
1363882361.703,,1.000000e+003,3.002084e+000,2.753928e-002,2.683397e-005,3,9.930043e-001,9.743889e-002,,,,,,,,,,,,,,24,3,4.000000e+000,8.903980e-003,0.000000e+000,0,,0,
1363884559.078,,1.000000e+003,2.502498e+000,3.121582e-002,4.090510e-006,3,9.931669e-001,1.310396e-002,,,,,,,,,,,,,,24,3,4.000000e+000,2.689838e-003,0.000000e+000,0,,0,
1363884962.703,,1.000000e+003,2.002516e+000,3.549015e-002,7.584856e-005,3,9.931777e-001,2.137172e-001,,,,,,,,,,,,,,24,3,4.000000e+000,7.004857e-003,0.000000e+000,0,,0,